Workbook

Sheet README
A1: Dock-to-Stock Bottleneck Analysis
A2: Simulated inbound dataset - 4,000 receipts - Jul to Sep 2026
A4: What this is | B4: A portfolio project that follows each inbound receipt from truck arrival to stock available in the system, and finds which step (or which wait between steps) holds stock back the most.
A5: IMPORTANT - data is simulated | B5: No real company data is used. The 4,000 receipts were generated by data/generate_dataset.py using lognormal timings and the assumptions listed on the Assumptions sheet. The findings show how the method works; they are not findings about a real warehouse.
A6: How to read it | B6: Start at Bottleneck_Score, then go through Process_Timeline, Heatmap, Vendor_Analysis, Warehouse_Shift, GRN_Ageing, Dock_Utilisation, Root_Cause, Decision_Model and finish with SOP.
A7: Sheets | B7: Assumptions (inputs) | Inbound_Data (the database: raw columns A-V, calculated columns W-AK) | one analysis sheet per output | Decision_Model (what-if) | SOP
A8: Colour legend | B8: Blue text on yellow = input you can change. Black = formula. Dark-blue header = raw data. Mid-blue header = calculated column.
A9: Change an assumption | B9: Edit SLA targets, score weights or priority cut-offs on the Assumptions sheet. Every score and table recalculates.
A10: Definitions | B10: Waiting = time a receipt sits between two steps (Gate Wait, Dock Wait, Unload-to-QC, QC-to-GRN, GRN-to-Putaway). Processing = time someone is actually working on it (Unloading, QC, GRN Processing, Putaway). Total Dock-to-Stock = Truck Arrival to Putaway Completed.
A11: Open receipts | B11: 160 receipts have no putaway yet (Pending or On Hold). Steps they have not reached are blank, so they never distort the later averages. Their waiting time is tracked in GRN_Ageing.
A12: Shift | B12: Shift is taken from the truck arrival hour: A = 06:00-14:00, B = 14:00-22:00, C = 22:00-06:00.

Sheet Assumptions
A1: Assumptions & Inputs
A2: Blue-on-yellow cells are inputs. Change them and the whole workbook recalculates.
A4: Segment | B4: Type | C4: SLA target (min) | D4: Data column | E4: Definition
A5: Gate Wait | B5: Waiting | C5: 30 | D5: Y | E5: Truck Arrival -> Dock Assigned
A6: Dock Wait | B6: Waiting | C6: 15 | D6: Z | E6: Dock Assigned -> Unloading Start
A7: Unloading | B7: Processing | C7: 60 | D7: AA | E7: Unloading Start -> Unloading End
A8: Unload-to-QC Wait | B8: Waiting | C8: 15 | D8: AB | E8: Unloading End -> QC Start
A9: QC | B9: Processing | C9: 45 | D9: AC | E9: QC Start -> QC End
A10: QC-to-GRN Wait | B10: Waiting | C10: 30 | D10: AD | E10: QC End -> GRN Start
A11: GRN Processing | B11: Processing | C11: 45 | D11: AE | E11: GRN Start -> GRN Completed
A12: GRN-to-Putaway Wait | B12: Waiting | C12: 20 | D12: AF | E12: GRN Completed -> Putaway Start
A13: Putaway | B13: Processing | C13: 40 | D13: AG | E13: Putaway Start -> Putaway Completed
A16: Bottleneck Score parameters
A17: Weight: share of total delay | B17: 0.4 | C17: Score = w1 x delay-share score + w2 x variability score + w3 x SLA-breach score
A18: Weight: variability (P90 / median) | B18: 0.3 | C18: Weights should add up to 100%
A19: Weight: % of receipts breaching SLA | B19: 0.3
A20: Variability cap (P90/median ratio) | B20: 4 | C20: A ratio at or above this scores 100 on variability
A21: Critical if score >= | B21: 70 | C21: Cut-offs are judgement calls; adjust to taste
A22: High if score >= | B22: 50
A23: Medium if score >= | B23: 35 | C23: Below this = Low
A24: Target total dock-to-stock (min) | B24: 300 | C24: Equals the sum of the nine segment SLAs (5 hours). Used for breach % on Warehouse_Shift
A25: Report date (as-of) | B25: 46297.333 | C25: Used to age open GRNs. Matches the generator
A26: Operating days in dataset | B26: 81 | C26: Distinct truck-arrival dates in the dataset (no Sunday receiving)
A27: Dock hours available per day | B27: 24 | C27: Docks assumed to run round the clock
A28: Docks in network | B28: 6 | C28: 2 docks per warehouse x 3 warehouses
A29: Weights check (should be 100%) | B29: =SUM(B17:B19) -> 1

Sheet Inbound_Data
A1: Receipt ID | B1: PO Number | C1: Vendor | D1: Warehouse | E1: SKU | F1: Category | G1: Dock ID | H1: Truck Arrival | I1: Dock Assigned | J1: Unloading Start | K1: Unloading End | L1: QC Start | M1: QC End | N1: GRN Start | O1: GRN Completed | P1: Putaway Start | Q1: Putaway Completed | R1: Quantity | S1: Short Quantity | T1: Damaged Quantity | U1: GRN Status | V1: Delay Cause | W1: Shift | X1: Arrival Hour | Y1: Gate Wait (min) | Z1: Dock Wait (min) | AA1: Unloading (min) | AB1: Unload-to-QC Wait (min) | AC1: QC (min) | AD1: QC-to-GRN Wait (min) | AE1: GRN Processing (min) | AF1: GRN-to-Putaway Wait (min) | AG1: Putaway (min) | AH1: Total Dock-to-Stock (min) | AI1: GRN Age (hrs) | AJ1: Worst SLA Ratio | AK1: Primary Delay Stage
A2: RCPT-00001 | B2: PO-26-77803 | C2: Vendor 06 | D2: Kalyan DC | E2: SKU-07-361 | F2: Staples | G2: KLN-D1 | H2: 46204.022 | I2: 46204.029 | J2: 46204.031 | K2: 46204.049 | L2: 46204.059 | M2: 46204.082 | N2: 46204.158 | O2: 46204.396 | P2: 46204.408 | Q2: 46204.416 | R2: 296 | S2: 17 | T2: 0 | U2: Completed - Discrepancy | V2: Vendor | W2: =IF(AND(X2>=6,X2<14),"A",IF(AND(X2>=14,X2<22),"B","C")) -> C | X2: =HOUR(H2) -> 0 | Y2: =ROUND((I2-H2)*1440,0) -> 11 | Z2: =ROUND((J2-I2)*1440,0) -> 3 | AA2: =ROUND((K2-J2)*1440,0) -> 25 | AB2: =ROUND((L2-K2)*1440,0) -> 15 | AC2: =ROUND((M2-L2)*1440,0) -> 33 | AD2: =IF(N2="","",ROUND((N2-M2)*1440,0)) -> 109 | AE2: =IF(O2="","",ROUND((O2-N2)*1440,0)) -> 343 | AF2: =IF(P2="","",ROUND((P2-O2)*1440,0)) -> 18 | AG2: =IF(Q2="","",ROUND((Q2-P2)*1440,0)) -> 11 | AH2: =IF(Q2="","",ROUND((Q2-H2)*1440,0)) -> 568 | AI2: =ROUND(IF(O2="",Assumptions!$B$25-K2,O2-K2)*24,1) -> 8.3 | AJ2: =ROUND(MAX(N(Y2)/Assumptions!$C$5, N(Z2)/Assumptions!$C$6, N(AA2)/Assumptions!$C$7, N(AB2)/Assumptions!$C$8, N(AC2)/Assumptions!$C$9, N(AD2)/Assumptions!$C$10, N(AE2)/Assumptions!$C$11, N(AF2)/Assumptions!$C$12, N(AG2)/Assumptions!$C$13),3) -> 7.622 | AK2: =IF(OR(U2="Pending",U2="On Hold"),"Open GRN (awaiting)",IF(AJ2<=1,"Within SLA",IF(ROUND(N(Y2)/Assumptions!$C$5,3)=AJ2,"Gate Wait",IF(ROUND(N(Z2)/Assumptions!$C$6,3)=AJ2,"Dock Wait",IF(ROUND(N(AA2)/Assumptions!$C$7,3)=AJ2,"Unloading",IF(ROUND(N(AB2)/Assumptions!$C$8,3)=AJ2,"Unload-to-QC Wait",IF(ROUND(N(AC2)/Assumptions!$C$9,3)=AJ2,"QC",IF(ROUND(N(AD2)/Assumptions!$C$10,3)=AJ2,"QC-to-GRN Wait",IF(ROUND(N(AE2)/Assumptions!$C$11,3)=AJ2,"GRN Processing",IF(ROUND(N(AF2)/Assumptions!$C$12,3)=AJ2,"GRN-to-Putaway Wait",IF(ROUND(N(AG2)/Assumptions!$C$13,3)=AJ2,"Putaway","Within SLA"))))))))))) -> GRN Processing
A3: RCPT-00002 | B3: PO-26-61546 | C3: Vendor 10 | D3: Kalyan DC | E3: SKU-03-317 | F3: Home Care | G3: KLN-D2 | H3: 46204.054 | I3: 46204.064 | J3: 46204.069 | K3: 46204.102 | L3: 46204.109 | M3: 46204.119 | N3: 46204.147 | O3: 46204.169 | P3: 46204.18 | Q3: 46204.212 | R3: 489 | S3: 0 | T3: 0 | U3: Completed | V3: System | W3: =IF(AND(X3>=6,X3<14),"A",IF(AND(X3>=14,X3<22),"B","C")) -> C | X3: =HOUR(H3) -> 1 | Y3: =ROUND((I3-H3)*1440,0) -> 14 | Z3: =ROUND((J3-I3)*1440,0) -> 8 | AA3: =ROUND((K3-J3)*1440,0) -> 47 | AB3: =ROUND((L3-K3)*1440,0) -> 10 | AC3: =ROUND((M3-L3)*1440,0) -> 14 | AD3: =IF(N3="","",ROUND((N3-M3)*1440,0)) -> 40 | AE3: =IF(O3="","",ROUND((O3-N3)*1440,0)) -> 33 | AF3: =IF(P3="","",ROUND((P3-O3)*1440,0)) -> 15 | AG3: =IF(Q3="","",ROUND((Q3-P3)*1440,0)) -> 46 | AH3: =IF(Q3="","",ROUND((Q3-H3)*1440,0)) -> 227 | AI3: =ROUND(IF(O3="",Assumptions!$B$25-K3,O3-K3)*24,1) -> 1.6 | AJ3: =ROUND(MAX(N(Y3)/Assumptions!$C$5, N(Z3)/Assumptions!$C$6, N(AA3)/Assumptions!$C$7, N(AB3)/Assumptions!$C$8, N(AC3)/Assumptions!$C$9, N(AD3)/Assumptions!$C$10, N(AE3)/Assumptions!$C$11, N(AF3)/Assumptions!$C$12, N(AG3)/Assumptions!$C$13),3) -> 1.333 | AK3: =IF(OR(U3="Pending",U3="On Hold"),"Open GRN (awaiting)",IF(AJ3<=1,"Within SLA",IF(ROUND(N(Y3)/Assumptions!$C$5,3)=AJ3,"Gate Wait",IF(ROUND(N(Z3)/Assumptions!$C$6,3)=AJ3,"Dock Wait",IF(ROUND(N(AA3)/Assumptions!$C$7,3)=AJ3,"Unloading",IF(ROUND(N(AB3)/Assumptions!$C$8,3)=AJ3,"Unload-to-QC Wait",IF(ROUND(N(AC3)/Assumptions!$C$9,3)=AJ3,"QC",IF(ROUND(N(AD3)/Assumptions!$C$10,3)=AJ3,"QC-to-GRN Wait",IF(ROUND(N(AE3)/Assumptions!$C$11,3)=AJ3,"GRN Processing",IF(ROUND(N(AF3)/Assumptions!$C$12,3)=AJ3,"GRN-to-Putaway Wait",IF(ROUND(N(AG3)/Assumptions!$C$13,3)=AJ3,"Putaway","Within SLA"))))))))))) -> QC-to-GRN Wait
A4: RCPT-00003 | B4: PO-26-59784 | C4: Vendor 12 | D4: Pimplas DC | E4: SKU-05-681 | F4: Personal Care | G4: PMP-D2 | H4: 46204.09 | I4: 46204.097 | J4: 46204.101 | K4: 46204.123 | L4: 46204.147 | M4: 46204.169 | N4: 46204.189 | O4: 46204.257 | P4: 46204.271 | Q4: 46204.287 | R4: 741 | S4: 0 | T4: 0 | U4: Completed | V4: Space / Equipment | W4: =IF(AND(X4>=6,X4<14),"A",IF(AND(X4>=14,X4<22),"B","C")) -> C | X4: =HOUR(H4) -> 2 | Y4: =ROUND((I4-H4)*1440,0) -> 11 | Z4: =ROUND((J4-I4)*1440,0) -> 5 | AA4: =ROUND((K4-J4)*1440,0) -> 32 | AB4: =ROUND((L4-K4)*1440,0) -> 34 | AC4: =ROUND((M4-L4)*1440,0) -> 32 | AD4: =IF(N4="","",ROUND((N4-M4)*1440,0)) -> 29 | AE4: =IF(O4="","",ROUND((O4-N4)*1440,0)) -> 98 | AF4: =IF(P4="","",ROUND((P4-O4)*1440,0)) -> 20 | AG4: =IF(Q4="","",ROUND((Q4-P4)*1440,0)) -> 23 | AH4: =IF(Q4="","",ROUND((Q4-H4)*1440,0)) -> 284 | AI4: =ROUND(IF(O4="",Assumptions!$B$25-K4,O4-K4)*24,1) -> 3.2 | AJ4: =ROUND(MAX(N(Y4)/Assumptions!$C$5, N(Z4)/Assumptions!$C$6, N(AA4)/Assumptions!$C$7, N(AB4)/Assumptions!$C$8, N(AC4)/Assumptions!$C$9, N(AD4)/Assumptions!$C$10, N(AE4)/Assumptions!$C$11, N(AF4)/Assumptions!$C$12, N(AG4)/Assumptions!$C$13),3) -> 2.267 | AK4: =IF(OR(U4="Pending",U4="On Hold"),"Open GRN (awaiting)",IF(AJ4<=1,"Within SLA",IF(ROUND(N(Y4)/Assumptions!$C$5,3)=AJ4,"Gate Wait",IF(ROUND(N(Z4)/Assumptions!$C$6,3)=AJ4,"Dock Wait",IF(ROUND(N(AA4)/Assumptions!$C$7,3)=AJ4,"Unloading",IF(ROUND(N(AB4)/Assumptions!$C$8,3)=AJ4,"Unload-to-QC Wait",IF(ROUND(N(AC4)/Assumptions!$C$9,3)=AJ4,"QC",IF(ROUND(N(AD4)/Assumptions!$C$10,3)=AJ4,"QC-to-GRN Wait",IF(ROUND(N(AE4)/Assumptions!$C$11,3)=AJ4,"GRN Processing",IF(ROUND(N(AF4)/Assumptions!$C$12,3)=AJ4,"GRN-to-Putaway Wait",IF(ROUND(N(AG4)/Assumptions!$C$13,3)=AJ4,"Putaway","Within SLA"))))))))))) -> Unload-to-QC Wait
A5: RCPT-00004 | B5: PO-26-75591 | C5: Vendor 04 | D5: Kalyan DC | E5: SKU-03-104 | F5: Home Care | G5: KLN-D1 | H5: 46204.291 | I5: 46204.304 | J5: 46204.307 | K5: 46204.333 | L5: 46204.348 | M5: 46204.368 | N5: 46204.374 | O5: 46204.396 | P5: 46204.401 | Q5: 46204.407 | R5: 223 | S5: 0 | T5: 1 | U5: Completed - Discrepancy | V5: Manpower | W5: =IF(AND(X5>=6,X5<14),"A",IF(AND(X5>=14,X5<22),"B","C")) -> A | X5: =HOUR(H5) -> 6 | Y5: =ROUND((I5-H5)*1440,0) -> 19 | Z5: =ROUND((J5-I5)*1440,0) -> 4 | AA5: =ROUND((K5-J5)*1440,0) -> 37 | AB5: =ROUND((L5-K5)*1440,0) -> 22 | AC5: =ROUND((M5-L5)*1440,0) -> 29 | AD5: =IF(N5="","",ROUND((N5-M5)*1440,0)) -> 8 | AE5: =IF(O5="","",ROUND((O5-N5)*1440,0)) -> 32 | AF5: =IF(P5="","",ROUND((P5-O5)*1440,0)) -> 8 | AG5: =IF(Q5="","",ROUND((Q5-P5)*1440,0)) -> 8 | AH5: =IF(Q5="","",ROUND((Q5-H5)*1440,0)) -> 167 | AI5: =ROUND(IF(O5="",Assumptions!$B$25-K5,O5-K5)*24,1) -> 1.5 | AJ5: =ROUND(MAX(N(Y5)/Assumptions!$C$5, N(Z5)/Assumptions!$C$6, N(AA5)/Assumptions!$C$7, N(AB5)/Assumptions!$C$8, N(AC5)/Assumptions!$C$9, N(AD5)/Assumptions!$C$10, N(AE5)/Assumptions!$C$11, N(AF5)/Assumptions!$C$12, N(AG5)/Assumptions!$C$13),3) -> 1.467 | AK5: =IF(OR(U5="Pending",U5="On Hold"),"Open GRN (awaiting)",IF(AJ5<=1,"Within SLA",IF(ROUND(N(Y5)/Assumptions!$C$5,3)=AJ5,"Gate Wait",IF(ROUND(N(Z5)/Assumptions!$C$6,3)=AJ5,"Dock Wait",IF(ROUND(N(AA5)/Assumptions!$C$7,3)=AJ5,"Unloading",IF(ROUND(N(AB5)/Assumptions!$C$8,3)=AJ5,"Unload-to-QC Wait",IF(ROUND(N(AC5)/Assumptions!$C$9,3)=AJ5,"QC",IF(ROUND(N(AD5)/Assumptions!$C$10,3)=AJ5,"QC-to-GRN Wait",IF(ROUND(N(AE5)/Assumptions!$C$11,3)=AJ5,"GRN Processing",IF(ROUND(N(AF5)/Assumptions!$C$12,3)=AJ5,"GRN-to-Putaway Wait",IF(ROUND(N(AG5)/Assumptions!$C$13,3)=AJ5,"Putaway","Within SLA"))))))))))) -> Unload-to-QC Wait
A6: RCPT-00005 | B6: PO-26-19735 | C6: Vendor 12 | D6: Bhiwandi DC | E6: SKU-04-688 | F6: Packaging | G6: BHW-D2 | H6: 46204.301 | I6: 46204.314 | J6: 46204.324 | K6: 46204.347 | L6: 46204.351 | M6: 46204.38 | N6: 46204.395 | O6: 46204.404 | P6: 46204.429 | Q6: 46204.44 | R6: 891 | S6: 0 | T6: 0 | U6: Completed | V6: Space / Equipment | W6: =IF(AND(X6>=6,X6<14),"A",IF(AND(X6>=14,X6<22),"B","C")) -> A | X6: =HOUR(H6) -> 7 | Y6: =ROUND((I6-H6)*1440,0) -> 18 | Z6: =ROUND((J6-I6)*1440,0) -> 15 | AA6: =ROUND((K6-J6)*1440,0) -> 32 | AB6: =ROUND((L6-K6)*1440,0) -> 7 | AC6: =ROUND((M6-L6)*1440,0) -> 41 | AD6: =IF(N6="","",ROUND((N6-M6)*1440,0)) -> 22 | AE6: =IF(O6="","",ROUND((O6-N6)*1440,0)) -> 13 | AF6: =IF(P6="","",ROUND((P6-O6)*1440,0)) -> 36 | AG6: =IF(Q6="","",ROUND((Q6-P6)*1440,0)) -> 16 | AH6: =IF(Q6="","",ROUND((Q6-H6)*1440,0)) -> 200 | AI6: =ROUND(IF(O6="",Assumptions!$B$25-K6,O6-K6)*24,1) -> 1.4 | AJ6: =ROUND(MAX(N(Y6)/Assumptions!$C$5, N(Z6)/Assumptions!$C$6, N(AA6)/Assumptions!$C$7, N(AB6)/Assumptions!$C$8, N(AC6)/Assumptions!$C$9, N(AD6)/Assumptions!$C$10, N(AE6)/Assumptions!$C$11, N(AF6)/Assumptions!$C$12, N(AG6)/Assumptions!$C$13),3) -> 1.8 | AK6: =IF(OR(U6="Pending",U6="On Hold"),"Open GRN (awaiting)",IF(AJ6<=1,"Within SLA",IF(ROUND(N(Y6)/Assumptions!$C$5,3)=AJ6,"Gate Wait",IF(ROUND(N(Z6)/Assumptions!$C$6,3)=AJ6,"Dock Wait",IF(ROUND(N(AA6)/Assumptions!$C$7,3)=AJ6,"Unloading",IF(ROUND(N(AB6)/Assumptions!$C$8,3)=AJ6,"Unload-to-QC Wait",IF(ROUND(N(AC6)/Assumptions!$C$9,3)=AJ6,"QC",IF(ROUND(N(AD6)/Assumptions!$C$10,3)=AJ6,"QC-to-GRN Wait",IF(ROUND(N(AE6)/Assumptions!$C$11,3)=AJ6,"GRN Processing",IF(ROUND(N(AF6)/Assumptions!$C$12,3)=AJ6,"GRN-to-Putaway Wait",IF(ROUND(N(AG6)/Assumptions!$C$13,3)=AJ6,"Putaway","Within SLA"))))))))))) -> GRN-to-Putaway Wait
A7: RCPT-00006 | B7: PO-26-36274 | C7: Vendor 11 | D7: Kalyan DC | E7: SKU-01-293 | F7: Beverages | G7: KLN-D1 | H7: 46204.31 | I7: 46204.342 | J7: 46204.349 | K7: 46204.396 | L7: 46204.408 | M7: 46204.429 | N7: 46204.485 | O7: 46204.516 | P7: 46204.533 | Q7: 46204.567 | R7: 355 | S7: 0 | T7: 0 | U7: Completed | V7: Documentation Mismatch | W7: =IF(AND(X7>=6,X7<14),"A",IF(AND(X7>=14,X7<22),"B","C")) -> A | X7: =HOUR(H7) -> 7 | Y7: =ROUND((I7-H7)*1440,0) -> 46 | Z7: =ROUND((J7-I7)*1440,0) -> 11 | AA7: =ROUND((K7-J7)*1440,0) -> 67 | AB7: =ROUND((L7-K7)*1440,0) -> 18 | AC7: =ROUND((M7-L7)*1440,0) -> 30 | AD7: =IF(N7="","",ROUND((N7-M7)*1440,0)) -> 80 | AE7: =IF(O7="","",ROUND((O7-N7)*1440,0)) -> 45 | AF7: =IF(P7="","",ROUND((P7-O7)*1440,0)) -> 25 | AG7: =IF(Q7="","",ROUND((Q7-P7)*1440,0)) -> 48 | AH7: =IF(Q7="","",ROUND((Q7-H7)*1440,0)) -> 370 | AI7: =ROUND(IF(O7="",Assumptions!$B$25-K7,O7-K7)*24,1) -> 2.9 | AJ7: =ROUND(MAX(N(Y7)/Assumptions!$C$5, N(Z7)/Assumptions!$C$6, N(AA7)/Assumptions!$C$7, N(AB7)/Assumptions!$C$8, N(AC7)/Assumptions!$C$9, N(AD7)/Assumptions!$C$10, N(AE7)/Assumptions!$C$11, N(AF7)/Assumptions!$C$12, N(AG7)/Assumptions!$C$13),3) -> 2.667 | AK7: =IF(OR(U7="Pending",U7="On Hold"),"Open GRN (awaiting)",IF(AJ7<=1,"Within SLA",IF(ROUND(N(Y7)/Assumptions!$C$5,3)=AJ7,"Gate Wait",IF(ROUND(N(Z7)/Assumptions!$C$6,3)=AJ7,"Dock Wait",IF(ROUND(N(AA7)/Assumptions!$C$7,3)=AJ7,"Unloading",IF(ROUND(N(AB7)/Assumptions!$C$8,3)=AJ7,"Unload-to-QC Wait",IF(ROUND(N(AC7)/Assumptions!$C$9,3)=AJ7,"QC",IF(ROUND(N(AD7)/Assumptions!$C$10,3)=AJ7,"QC-to-GRN Wait",IF(ROUND(N(AE7)/Assumptions!$C$11,3)=AJ7,"GRN Processing",IF(ROUND(N(AF7)/Assumptions!$C$12,3)=AJ7,"GRN-to-Putaway Wait",IF(ROUND(N(AG7)/Assumptions!$C$13,3)=AJ7,"Putaway","Within SLA"))))))))))) -> QC-to-GRN Wait
A8: RCPT-00007 | B8: PO-26-32694 | C8: Vendor 05 | D8: Kalyan DC | E8: SKU-03-837 | F8: Home Care | G8: KLN-D2 | H8: 46204.31 | I8: 46204.318 | J8: 46204.326 | K8: 46204.366 | L8: 46204.374 | M8: 46204.402 | N8: 46204.658 | O8: 46204.728 | P8: 46204.762 | Q8: 46204.772 | R8: 1670 | S8: 0 | T8: 0 | U8: Completed | V8: System | W8: =IF(AND(X8>=6,X8<14),"A",IF(AND(X8>=14,X8<22),"B","C")) -> A | X8: =HOUR(H8) -> 7 | Y8: =ROUND((I8-H8)*1440,0) -> 12 | Z8: =ROUND((J8-I8)*1440,0) -> 11 | AA8: =ROUND((K8-J8)*1440,0) -> 58 | AB8: =ROUND((L8-K8)*1440,0) -> 11 | AC8: =ROUND((M8-L8)*1440,0) -> 41 | AD8: =IF(N8="","",ROUND((N8-M8)*1440,0)) -> 369 | AE8: =IF(O8="","",ROUND((O8-N8)*1440,0)) -> 101 | AF8: =IF(P8="","",ROUND((P8-O8)*1440,0)) -> 49 | AG8: =IF(Q8="","",ROUND((Q8-P8)*1440,0)) -> 13 | AH8: =IF(Q8="","",ROUND((Q8-H8)*1440,0)) -> 665 | AI8: =ROUND(IF(O8="",Assumptions!$B$25-K8,O8-K8)*24,1) -> 8.7 | AJ8: =ROUND(MAX(N(Y8)/Assumptions!$C$5, N(Z8)/Assumptions!$C$6, N(AA8)/Assumptions!$C$7, N(AB8)/Assumptions!$C$8, N(AC8)/Assumptions!$C$9, N(AD8)/Assumptions!$C$10, N(AE8)/Assumptions!$C$11, N(AF8)/Assumptions!$C$12, N(AG8)/Assumptions!$C$13),3) -> 12.3 | AK8: =IF(OR(U8="Pending",U8="On Hold"),"Open GRN (awaiting)",IF(AJ8<=1,"Within SLA",IF(ROUND(N(Y8)/Assumptions!$C$5,3)=AJ8,"Gate Wait",IF(ROUND(N(Z8)/Assumptions!$C$6,3)=AJ8,"Dock Wait",IF(ROUND(N(AA8)/Assumptions!$C$7,3)=AJ8,"Unloading",IF(ROUND(N(AB8)/Assumptions!$C$8,3)=AJ8,"Unload-to-QC Wait",IF(ROUND(N(AC8)/Assumptions!$C$9,3)=AJ8,"QC",IF(ROUND(N(AD8)/Assumptions!$C$10,3)=AJ8,"QC-to-GRN Wait",IF(ROUND(N(AE8)/Assumptions!$C$11,3)=AJ8,"GRN Processing",IF(ROUND(N(AF8)/Assumptions!$C$12,3)=AJ8,"GRN-to-Putaway Wait",IF(ROUND(N(AG8)/Assumptions!$C$13,3)=AJ8,"Putaway","Within SLA"))))))))))) -> QC-to-GRN Wait
A9: RCPT-00008 | B9: PO-26-91108 | C9: Vendor 11 | D9: Kalyan DC | E9: SKU-01-312 | F9: Beverages | G9: KLN-D2 | H9: 46204.334 | I9: 46204.347 | J9: 46204.358 | K9: 46204.389 | L9: 46204.392 | M9: 46204.424 | N9: 46204.508 | O9: 46204.562 | P9: 46204.572 | Q9: 46204.595 | R9: 729 | S9: 0 | T9: 0 | U9: Completed | V9: Manpower | W9: =IF(AND(X9>=6,X9<14),"A",IF(AND(X9>=14,X9<22),"B","C")) -> A | X9: =HOUR(H9) -> 8 | Y9: =ROUND((I9-H9)*1440,0) -> 19 | Z9: =ROUND((J9-I9)*1440,0) -> 15 | AA9: =ROUND((K9-J9)*1440,0) -> 45 | AB9: =ROUND((L9-K9)*1440,0) -> 5 | AC9: =ROUND((M9-L9)*1440,0) -> 46 | AD9: =IF(N9="","",ROUND((N9-M9)*1440,0)) -> 120 | AE9: =IF(O9="","",ROUND((O9-N9)*1440,0)) -> 79 | AF9: =IF(P9="","",ROUND((P9-O9)*1440,0)) -> 14 | AG9: =IF(Q9="","",ROUND((Q9-P9)*1440,0)) -> 33 | AH9: =IF(Q9="","",ROUND((Q9-H9)*1440,0)) -> 376 | AI9: =ROUND(IF(O9="",Assumptions!$B$25-K9,O9-K9)*24,1) -> 4.2 | AJ9: =ROUND(MAX(N(Y9)/Assumptions!$C$5, N(Z9)/Assumptions!$C$6, N(AA9)/Assumptions!$C$7, N(AB9)/Assumptions!$C$8, N(AC9)/Assumptions!$C$9, N(AD9)/Assumptions!$C$10, N(AE9)/Assumptions!$C$11, N(AF9)/Assumptions!$C$12, N(AG9)/Assumptions!$C$13),3) -> 4 | AK9: =IF(OR(U9="Pending",U9="On Hold"),"Open GRN (awaiting)",IF(AJ9<=1,"Within SLA",IF(ROUND(N(Y9)/Assumptions!$C$5,3)=AJ9,"Gate Wait",IF(ROUND(N(Z9)/Assumptions!$C$6,3)=AJ9,"Dock Wait",IF(ROUND(N(AA9)/Assumptions!$C$7,3)=AJ9,"Unloading",IF(ROUND(N(AB9)/Assumptions!$C$8,3)=AJ9,"Unload-to-QC Wait",IF(ROUND(N(AC9)/Assumptions!$C$9,3)=AJ9,"QC",IF(ROUND(N(AD9)/Assumptions!$C$10,3)=AJ9,"QC-to-GRN Wait",IF(ROUND(N(AE9)/Assumptions!$C$11,3)=AJ9,"GRN Processing",IF(ROUND(N(AF9)/Assumptions!$C$12,3)=AJ9,"GRN-to-Putaway Wait",IF(ROUND(N(AG9)/Assumptions!$C$13,3)=AJ9,"Putaway","Within SLA"))))))))))) -> QC-to-GRN Wait
A10: RCPT-00009 | B10: PO-26-48414 | C10: Vendor 05 | D10: Bhiwandi DC | E10: SKU-03-464 | F10: Home Care | G10: BHW-D1 | H10: 46204.335 | I10: 46204.352 | J10: 46204.358 | K10: 46204.403 | L10: 46204.407 | M10: 46204.465 | N10: 46204.486 | O10: 46204.527 | P10: 46204.539 | Q10: 46204.546 | R10: 466 | S10: 0 | T10: 3 | U10: Completed - Discrepancy | V10: Vendor | W10: =IF(AND(X10>=6,X10<14),"A",IF(AND(X10>=14,X10<22),"B","C")) -> A | X10: =HOUR(H10) -> 8 | Y10: =ROUND((I10-H10)*1440,0) -> 24 | Z10: =ROUND((J10-I10)*1440,0) -> 8 | AA10: =ROUND((K10-J10)*1440,0) -> 66 | AB10: =ROUND((L10-K10)*1440,0) -> 5 | AC10: =ROUND((M10-L10)*1440,0) -> 83 | AD10: =IF(N10="","",ROUND((N10-M10)*1440,0)) -> 31 | AE10: =IF(O10="","",ROUND((O10-N10)*1440,0)) -> 59 | AF10: =IF(P10="","",ROUND((P10-O10)*1440,0)) -> 17 | AG10: =IF(Q10="","",ROUND((Q10-P10)*1440,0)) -> 10 | AH10: =IF(Q10="","",ROUND((Q10-H10)*1440,0)) -> 303 | AI10: =ROUND(IF(O10="",Assumptions!$B$25-K10,O10-K10)*24,1) -> 3 | AJ10: =ROUND(MAX(N(Y10)/Assumptions!$C$5, N(Z10)/Assumptions!$C$6, N(AA10)/Assumptions!$C$7, N(AB10)/Assumptions!$C$8, N(AC10)/Assumptions!$C$9, N(AD10)/Assumptions!$C$10, N(AE10)/Assumptions!$C$11, N(AF10)/Assumptions!$C$12, N(AG10)/Assumptions!$C$13),3) -> 1.844 | AK10: =IF(OR(U10="Pending",U10="On Hold"),"Open GRN (awaiting)",IF(AJ10<=1,"Within SLA",IF(ROUND(N(Y10)/Assumptions!$C$5,3)=AJ10,"Gate Wait",IF(ROUND(N(Z10)/Assumptions!$C$6,3)=AJ10,"Dock Wait",IF(ROUND(N(AA10)/Assumptions!$C$7,3)=AJ10,"Unloading",IF(ROUND(N(AB10)/Assumptions!$C$8,3)=AJ10,"Unload-to-QC Wait",IF(ROUND(N(AC10)/Assumptions!$C$9,3)=AJ10,"QC",IF(ROUND(N(AD10)/Assumptions!$C$10,3)=AJ10,"QC-to-GRN Wait",IF(ROUND(N(AE10)/Assumptions!$C$11,3)=AJ10,"GRN Processing",IF(ROUND(N(AF10)/Assumptions!$C$12,3)=AJ10,"GRN-to-Putaway Wait",IF(ROUND(N(AG10)/Assumptions!$C$13,3)=AJ10,"Putaway","Within SLA"))))))))))) -> QC
A11: RCPT-00010 | B11: PO-26-81898 | C11: Vendor 08 | D11: Bhiwandi DC | E11: SKU-02-707 | F11: Dairy & Frozen | G11: BHW-D2 | H11: 46204.337 | I11: 46204.364 | J11: 46204.376 | K11: 46204.397 | L11: 46204.406 | M11: 46204.42 | N11: 46204.424 | O11: 46204.442 | P11: 46204.451 | Q11: 46204.463 | R11: 78 | S11: 0 | T11: 0 | U11: Completed | V11: Vendor | W11: =IF(AND(X11>=6,X11<14),"A",IF(AND(X11>=14,X11<22),"B","C")) -> A | X11: =HOUR(H11) -> 8 | Y11: =ROUND((I11-H11)*1440,0) -> 39 | Z11: =ROUND((J11-I11)*1440,0) -> 17 | AA11: =ROUND((K11-J11)*1440,0) -> 31 | AB11: =ROUND((L11-K11)*1440,0) -> 13 | AC11: =ROUND((M11-L11)*1440,0) -> 20 | AD11: =IF(N11="","",ROUND((N11-M11)*1440,0)) -> 5 | AE11: =IF(O11="","",ROUND((O11-N11)*1440,0)) -> 26 | AF11: =IF(P11="","",ROUND((P11-O11)*1440,0)) -> 13 | AG11: =IF(Q11="","",ROUND((Q11-P11)*1440,0)) -> 18 | AH11: =IF(Q11="","",ROUND((Q11-H11)*1440,0)) -> 182 | AI11: =ROUND(IF(O11="",Assumptions!$B$25-K11,O11-K11)*24,1) -> 1.1 | AJ11: =ROUND(MAX(N(Y11)/Assumptions!$C$5, N(Z11)/Assumptions!$C$6, N(AA11)/Assumptions!$C$7, N(AB11)/Assumptions!$C$8, N(AC11)/Assumptions!$C$9, N(AD11)/Assumptions!$C$10, N(AE11)/Assumptions!$C$11, N(AF11)/Assumptions!$C$12, N(AG11)/Assumptions!$C$13),3) -> 1.3 | AK11: =IF(OR(U11="Pending",U11="On Hold"),"Open GRN (awaiting)",IF(AJ11<=1,"Within SLA",IF(ROUND(N(Y11)/Assumptions!$C$5,3)=AJ11,"Gate Wait",IF(ROUND(N(Z11)/Assumptions!$C$6,3)=AJ11,"Dock Wait",IF(ROUND(N(AA11)/Assumptions!$C$7,3)=AJ11,"Unloading",IF(ROUND(N(AB11)/Assumptions!$C$8,3)=AJ11,"Unload-to-QC Wait",IF(ROUND(N(AC11)/Assumptions!$C$9,3)=AJ11,"QC",IF(ROUND(N(AD11)/Assumptions!$C$10,3)=AJ11,"QC-to-GRN Wait",IF(ROUND(N(AE11)/Assumptions!$C$11,3)=AJ11,"GRN Processing",IF(ROUND(N(AF11)/Assumptions!$C$12,3)=AJ11,"GRN-to-Putaway Wait",IF(ROUND(N(AG11)/Assumptions!$C$13,3)=AJ11,"Putaway","Within SLA"))))))))))) -> Gate Wait
A12: RCPT-00011 | B12: PO-26-85314 | C12: Vendor 02 | D12: Pimplas DC | E12: SKU-06-829 | F12: Snacks | G12: PMP-D1 | H12: 46204.341 | I12: 46204.346 | J12: 46204.357 | K12: 46204.389 | L12: 46204.442 | M12: 46204.46 | N12: 46204.526 | O12: 46204.549 | P12: 46204.556 | Q12: 46204.612 | R12: 324 | S12: 0 | T12: 0 | U12: Completed | V12: Space / Equipment | W12: =IF(AND(X12>=6,X12<14),"A",IF(AND(X12>=14,X12<22),"B","C")) -> A | X12: =HOUR(H12) -> 8 | Y12: =ROUND((I12-H12)*1440,0) -> 7 | Z12: =ROUND((J12-I12)*1440,0) -> 16 | AA12: =ROUND((K12-J12)*1440,0) -> 46 | AB12: =ROUND((L12-K12)*1440,0) -> 77 | AC12: =ROUND((M12-L12)*1440,0) -> 25 | AD12: =IF(N12="","",ROUND((N12-M12)*1440,0)) -> 96 | AE12: =IF(O12="","",ROUND((O12-N12)*1440,0)) -> 33 | AF12: =IF(P12="","",ROUND((P12-O12)*1440,0)) -> 10 | AG12: =IF(Q12="","",ROUND((Q12-P12)*1440,0)) -> 80 | AH12: =IF(Q12="","",ROUND((Q12-H12)*1440,0)) -> 390 | AI12: =ROUND(IF(O12="",Assumptions!$B$25-K12,O12-K12)*24,1) -> 3.9 | AJ12: =ROUND(MAX(N(Y12)/Assumptions!$C$5, N(Z12)/Assumptions!$C$6, N(AA12)/Assumptions!$C$7, N(AB12)/Assumptions!$C$8, N(AC12)/Assumptions!$C$9, N(AD12)/Assumptions!$C$10, N(AE12)/Assumptions!$C$11, N(AF12)/Assumptions!$C$12, N(AG12)/Assumptions!$C$13),3) -> 5.133 | AK12: =IF(OR(U12="Pending",U12="On Hold"),"Open GRN (awaiting)",IF(AJ12<=1,"Within SLA",IF(ROUND(N(Y12)/Assumptions!$C$5,3)=AJ12,"Gate Wait",IF(ROUND(N(Z12)/Assumptions!$C$6,3)=AJ12,"Dock Wait",IF(ROUND(N(AA12)/Assumptions!$C$7,3)=AJ12,"Unloading",IF(ROUND(N(AB12)/Assumptions!$C$8,3)=AJ12,"Unload-to-QC Wait",IF(ROUND(N(AC12)/Assumptions!$C$9,3)=AJ12,"QC",IF(ROUND(N(AD12)/Assumptions!$C$10,3)=AJ12,"QC-to-GRN Wait",IF(ROUND(N(AE12)/Assumptions!$C$11,3)=AJ12,"GRN Processing",IF(ROUND(N(AF12)/Assumptions!$C$12,3)=AJ12,"GRN-to-Putaway Wait",IF(ROUND(N(AG12)/Assumptions!$C$13,3)=AJ12,"Putaway","Within SLA"))))))))))) -> Unload-to-QC Wait
A13: RCPT-00012 | B13: PO-26-60031 | C13: Vendor 04 | D13: Bhiwandi DC | E13: SKU-05-867 | F13: Personal Care | G13: BHW-D1 | H13: 46204.349 | I13: 46204.368 | J13: 46204.385 | K13: 46204.416 | L13: 46204.428 | M13: 46204.464 | N13: 46204.506 | O13: 46204.521 | P13: 46204.542 | Q13: 46204.556 | R13: 401 | S13: 0 | T13: 0 | U13: Completed | V13: System | W13: =IF(AND(X13>=6,X13<14),"A",IF(AND(X13>=14,X13<22),"B","C")) -> A | X13: =HOUR(H13) -> 8 | Y13: =ROUND((I13-H13)*1440,0) -> 28 | Z13: =ROUND((J13-I13)*1440,0) -> 24 | AA13: =ROUND((K13-J13)*1440,0) -> 45 | AB13: =ROUND((L13-K13)*1440,0) -> 18 | AC13: =ROUND((M13-L13)*1440,0) -> 51 | AD13: =IF(N13="","",ROUND((N13-M13)*1440,0)) -> 61 | AE13: =IF(O13="","",ROUND((O13-N13)*1440,0)) -> 21 | AF13: =IF(P13="","",ROUND((P13-O13)*1440,0)) -> 31 | AG13: =IF(Q13="","",ROUND((Q13-P13)*1440,0)) -> 20 | AH13: =IF(Q13="","",ROUND((Q13-H13)*1440,0)) -> 299 | AI13: =ROUND(IF(O13="",Assumptions!$B$25-K13,O13-K13)*24,1) -> 2.5 | AJ13: =ROUND(MAX(N(Y13)/Assumptions!$C$5, N(Z13)/Assumptions!$C$6, N(AA13)/Assumptions!$C$7, N(AB13)/Assumptions!$C$8, N(AC13)/Assumptions!$C$9, N(AD13)/Assumptions!$C$10, N(AE13)/Assumptions!$C$11, N(AF13)/Assumptions!$C$12, N(AG13)/Assumptions!$C$13),3) -> 2.033 | AK13: =IF(OR(U13="Pending",U13="On Hold"),"Open GRN (awaiting)",IF(AJ13<=1,"Within SLA",IF(ROUND(N(Y13)/Assumptions!$C$5,3)=AJ13,"Gate Wait",IF(ROUND(N(Z13)/Assumptions!$C$6,3)=AJ13,"Dock Wait",IF(ROUND(N(AA13)/Assumptions!$C$7,3)=AJ13,"Unloading",IF(ROUND(N(AB13)/Assumptions!$C$8,3)=AJ13,"Unload-to-QC Wait",IF(ROUND(N(AC13)/Assumptions!$C$9,3)=AJ13,"QC",IF(ROUND(N(AD13)/Assumptions!$C$10,3)=AJ13,"QC-to-GRN Wait",IF(ROUND(N(AE13)/Assumptions!$C$11,3)=AJ13,"GRN Processing",IF(ROUND(N(AF13)/Assumptions!$C$12,3)=AJ13,"GRN-to-Putaway Wait",IF(ROUND(N(AG13)/Assumptions!$C$13,3)=AJ13,"Putaway","Within SLA"))))))))))) -> QC-to-GRN Wait
... A3008: RCPT-03007 | B3008: PO-26-70581 | C3008: Vendor 12 | D3008: Pimplas DC | E3008: SKU-04-767 | F3008: Packaging | G3008: PMP-D1 | H3008: 46276.599 | I3008: 46276.614 | J3008: 46276.621 | K3008: 46276.642 | L3008: 46276.649 | M3008: 46276.659 | N3008: 46276.681 | O3008: 46276.78 | P3008: 46276.798 | Q3008: 46276.811 | R3008: 427 | S3008: 0 | T3008: 0 | U3008: Completed | V3008: Manpower | W3008: =IF(AND(X3008>=6,X3008<14),"A",IF(AND(X3008>=14,X3008<22),"B","C")) -> B | X3008: =HOUR(H3008) -> 14 | Y3008: =ROUND((I3008-H3008)*1440,0) -> 21 | Z3008: =ROUND((J3008-I3008)*1440,0) -> 10 | AA3008: =ROUND((K3008-J3008)*1440,0) -> 30 | AB3008: =ROUND((L3008-K3008)*1440,0) -> 11 | AC3008: =ROUND((M3008-L3008)*1440,0) -> 14 | AD3008: =IF(N3008="","",ROUND((N3008-M3008)*1440,0)) -> 32 | AE3008: =IF(O3008="","",ROUND((O3008-N3008)*1440,0)) -> 142 | AF3008: =IF(P3008="","",ROUND((P3008-O3008)*1440,0)) -> 26 | AG3008: =IF(Q3008="","",ROUND((Q3008-P3008)*1440,0)) -> 19 | AH3008: =IF(Q3008="","",ROUND((Q3008-H3008)*1440,0)) -> 305 | AI3008: =ROUND(IF(O3008="",Assumptions!$B$25-K3008,O3008-K3008)*24,1) -> 3.3 | AJ3008: =ROUND(MAX(N(Y3008)/Assumptions!$C$5, N(Z3008)/Assumptions!$C$6, N(AA3008)/Assumptions!$C$7, N(AB3008)/Assumptions!$C$8, N(AC3008)/Assumptions!$C$9, N(AD3008)/Assumptions!$C$10, N(AE3008)/Assumptions!$C$11, N(AF3008)/Assumptions!$C$12, N(AG3008)/Assumptions!$C$13),3) -> 3.156 | AK3008: =IF(OR(U3008="Pending",U3008="On Hold"),"Open GRN (awaiting)",IF(AJ3008<=1,"Within SLA",IF(ROUND(N(Y3008)/Assumptions!$C$5,3)=AJ3008,"Gate Wait",IF(ROUND(N(Z3008)/Assumptions!$C$6,3)=AJ3008,"Dock Wait",IF(ROUND(N(AA3008)/Assumptions!$C$7,3)=AJ3008,"Unloading",IF(ROUND(N(AB3008)/Assumptions!$C$8,3)=AJ3008,"Unload-to-QC Wait",IF(ROUND(N(AC3008)/Assumptions!$C$9,3)=AJ3008,"QC",IF(ROUND(N(AD3008)/Assumptions!$C$10,3)=AJ3008,"QC-to-GRN Wait",IF(ROUND(N(AE3008)/Assumptions!$C$11,3)=AJ3008,"GRN Processing",IF(ROUND(N(AF3008)/Assumptions!$C$12,3)=AJ3008,"GRN-to-Putaway Wait",IF(ROUND(N(AG3008)/Assumptions!$C$13,3)=AJ3008,"Putaway","Within SLA"))))))))))) -> GRN Processing
A3009: RCPT-03008 | B3009: PO-26-90445 | C3009: Vendor 10 | D3009: Pimplas DC | E3009: SKU-03-839 | F3009: Home Care | G3009: PMP-D1 | H3009: 46276.608 | I3009: 46276.635 | J3009: 46276.643 | K3009: 46276.687 | L3009: 46276.691 | M3009: 46276.703 | R3009: 242 | S3009: 0 | T3009: 0 | U3009: On Hold | V3009: Vendor | W3009: =IF(AND(X3009>=6,X3009<14),"A",IF(AND(X3009>=14,X3009<22),"B","C")) -> B | X3009: =HOUR(H3009) -> 14 | Y3009: =ROUND((I3009-H3009)*1440,0) -> 39 | Z3009: =ROUND((J3009-I3009)*1440,0) -> 12 | AA3009: =ROUND((K3009-J3009)*1440,0) -> 63 | AB3009: =ROUND((L3009-K3009)*1440,0) -> 6 | AC3009: =ROUND((M3009-L3009)*1440,0) -> 17 | AD3009: =IF(N3009="","",ROUND((N3009-M3009)*1440,0)) | AE3009: =IF(O3009="","",ROUND((O3009-N3009)*1440,0)) | AF3009: =IF(P3009="","",ROUND((P3009-O3009)*1440,0)) | AG3009: =IF(Q3009="","",ROUND((Q3009-P3009)*1440,0)) | AH3009: =IF(Q3009="","",ROUND((Q3009-H3009)*1440,0)) | AI3009: =ROUND(IF(O3009="",Assumptions!$B$25-K3009,O3009-K3009)*24,1) -> 495.5 | AJ3009: =ROUND(MAX(N(Y3009)/Assumptions!$C$5, N(Z3009)/Assumptions!$C$6, N(AA3009)/Assumptions!$C$7, N(AB3009)/Assumptions!$C$8, N(AC3009)/Assumptions!$C$9, N(AD3009)/Assumptions!$C$10, N(AE3009)/Assumptions!$C$11, N(AF3009)/Assumptions!$C$12, N(AG3009)/Assumptions!$C$13),3) -> 1.3 | AK3009: =IF(OR(U3009="Pending",U3009="On Hold"),"Open GRN (awaiting)",IF(AJ3009<=1,"Within SLA",IF(ROUND(N(Y3009)/Assumptions!$C$5,3)=AJ3009,"Gate Wait",IF(ROUND(N(Z3009)/Assumptions!$C$6,3)=AJ3009,"Dock Wait",IF(ROUND(N(AA3009)/Assumptions!$C$7,3)=AJ3009,"Unloading",IF(ROUND(N(AB3009)/Assumptions!$C$8,3)=AJ3009,"Unload-to-QC Wait",IF(ROUND(N(AC3009)/Assumptions!$C$9,3)=AJ3009,"QC",IF(ROUND(N(AD3009)/Assumptions!$C$10,3)=AJ3009,"QC-to-GRN Wait",IF(ROUND(N(AE3009)/Assumptions!$C$11,3)=AJ3009,"GRN Processing",IF(ROUND(N(AF3009)/Assumptions!$C$12,3)=AJ3009,"GRN-to-Putaway Wait",IF(ROUND(N(AG3009)/Assumptions!$C$13,3)=AJ3009,"Putaway","Within SLA"))))))))))) -> Open GRN (awaiting)
A3010: RCPT-03009 | B3010: PO-26-55550 | C3010: Vendor 06 | D3010: Bhiwandi DC | E3010: SKU-07-363 | F3010: Staples | G3010: BHW-D2 | H3010: 46276.614 | I3010: 46276.631 | J3010: 46276.633 | K3010: 46276.648 | L3010: 46276.66 | M3010: 46276.684 | N3010: 46276.705 | O3010: 46276.724 | P3010: 46276.736 | Q3010: 46276.755 | R3010: 465 | S3010: 0 | T3010: 0 | U3010: Completed | V3010: Space / Equipment | W3010: =IF(AND(X3010>=6,X3010<14),"A",IF(AND(X3010>=14,X3010<22),"B","C")) -> B | X3010: =HOUR(H3010) -> 14 | Y3010: =ROUND((I3010-H3010)*1440,0) -> 25 | Z3010: =ROUND((J3010-I3010)*1440,0) -> 3 | AA3010: =ROUND((K3010-J3010)*1440,0) -> 21 | AB3010: =ROUND((L3010-K3010)*1440,0) -> 18 | AC3010: =ROUND((M3010-L3010)*1440,0) -> 34 | AD3010: =IF(N3010="","",ROUND((N3010-M3010)*1440,0)) -> 30 | AE3010: =IF(O3010="","",ROUND((O3010-N3010)*1440,0)) -> 27 | AF3010: =IF(P3010="","",ROUND((P3010-O3010)*1440,0)) -> 18 | AG3010: =IF(Q3010="","",ROUND((Q3010-P3010)*1440,0)) -> 27 | AH3010: =IF(Q3010="","",ROUND((Q3010-H3010)*1440,0)) -> 203 | AI3010: =ROUND(IF(O3010="",Assumptions!$B$25-K3010,O3010-K3010)*24,1) -> 1.8 | AJ3010: =ROUND(MAX(N(Y3010)/Assumptions!$C$5, N(Z3010)/Assumptions!$C$6, N(AA3010)/Assumptions!$C$7, N(AB3010)/Assumptions!$C$8, N(AC3010)/Assumptions!$C$9, N(AD3010)/Assumptions!$C$10, N(AE3010)/Assumptions!$C$11, N(AF3010)/Assumptions!$C$12, N(AG3010)/Assumptions!$C$13),3) -> 1.2 | AK3010: =IF(OR(U3010="Pending",U3010="On Hold"),"Open GRN (awaiting)",IF(AJ3010<=1,"Within SLA",IF(ROUND(N(Y3010)/Assumptions!$C$5,3)=AJ3010,"Gate Wait",IF(ROUND(N(Z3010)/Assumptions!$C$6,3)=AJ3010,"Dock Wait",IF(ROUND(N(AA3010)/Assumptions!$C$7,3)=AJ3010,"Unloading",IF(ROUND(N(AB3010)/Assumptions!$C$8,3)=AJ3010,"Unload-to-QC Wait",IF(ROUND(N(AC3010)/Assumptions!$C$9,3)=AJ3010,"QC",IF(ROUND(N(AD3010)/Assumptions!$C$10,3)=AJ3010,"QC-to-GRN Wait",IF(ROUND(N(AE3010)/Assumptions!$C$11,3)=AJ3010,"GRN Processing",IF(ROUND(N(AF3010)/Assumptions!$C$12,3)=AJ3010,"GRN-to-Putaway Wait",IF(ROUND(N(AG3010)/Assumptions!$C$13,3)=AJ3010,"Putaway","Within SLA"))))))))))) -> Unload-to-QC Wait
A3011: RCPT-03010 | B3011: PO-26-78213 | C3011: Vendor 02 | D3011: Bhiwandi DC | E3011: SKU-06-402 | F3011: Snacks | G3011: BHW-D2 | H3011: 46276.622 | I3011: 46276.633 | J3011: 46276.635 | K3011: 46276.665 | L3011: 46276.681 | M3011: 46276.713 | N3011: 46276.732 | O3011: 46276.74 | P3011: 46276.765 | Q3011: 46276.799 | R3011: 649 | S3011: 0 | T3011: 0 | U3011: Completed | V3011: Manpower | W3011: =IF(AND(X3011>=6,X3011<14),"A",IF(AND(X3011>=14,X3011<22),"B","C")) -> B | X3011: =HOUR(H3011) -> 14 | Y3011: =ROUND((I3011-H3011)*1440,0) -> 15 | Z3011: =ROUND((J3011-I3011)*1440,0) -> 4 | AA3011: =ROUND((K3011-J3011)*1440,0) -> 43 | AB3011: =ROUND((L3011-K3011)*1440,0) -> 22 | AC3011: =ROUND((M3011-L3011)*1440,0) -> 47 | AD3011: =IF(N3011="","",ROUND((N3011-M3011)*1440,0)) -> 27 | AE3011: =IF(O3011="","",ROUND((O3011-N3011)*1440,0)) -> 11 | AF3011: =IF(P3011="","",ROUND((P3011-O3011)*1440,0)) -> 36 | AG3011: =IF(Q3011="","",ROUND((Q3011-P3011)*1440,0)) -> 49 | AH3011: =IF(Q3011="","",ROUND((Q3011-H3011)*1440,0)) -> 254 | AI3011: =ROUND(IF(O3011="",Assumptions!$B$25-K3011,O3011-K3011)*24,1) -> 1.8 | AJ3011: =ROUND(MAX(N(Y3011)/Assumptions!$C$5, N(Z3011)/Assumptions!$C$6, N(AA3011)/Assumptions!$C$7, N(AB3011)/Assumptions!$C$8, N(AC3011)/Assumptions!$C$9, N(AD3011)/Assumptions!$C$10, N(AE3011)/Assumptions!$C$11, N(AF3011)/Assumptions!$C$12, N(AG3011)/Assumptions!$C$13),3) -> 1.8 | AK3011: =IF(OR(U3011="Pending",U3011="On Hold"),"Open GRN (awaiting)",IF(AJ3011<=1,"Within SLA",IF(ROUND(N(Y3011)/Assumptions!$C$5,3)=AJ3011,"Gate Wait",IF(ROUND(N(Z3011)/Assumptions!$C$6,3)=AJ3011,"Dock Wait",IF(ROUND(N(AA3011)/Assumptions!$C$7,3)=AJ3011,"Unloading",IF(ROUND(N(AB3011)/Assumptions!$C$8,3)=AJ3011,"Unload-to-QC Wait",IF(ROUND(N(AC3011)/Assumptions!$C$9,3)=AJ3011,"QC",IF(ROUND(N(AD3011)/Assumptions!$C$10,3)=AJ3011,"QC-to-GRN Wait",IF(ROUND(N(AE3011)/Assumptions!$C$11,3)=AJ3011,"GRN Processing",IF(ROUND(N(AF3011)/Assumptions!$C$12,3)=AJ3011,"GRN-to-Putaway Wait",IF(ROUND(N(AG3011)/Assumptions!$C$13,3)=AJ3011,"Putaway","Within SLA"))))))))))) -> GRN-to-Putaway Wait
A3012: RCPT-03011 | B3012: PO-26-60478 | C3012: Vendor 08 | D3012: Kalyan DC | E3012: SKU-02-481 | F3012: Dairy & Frozen | G3012: KLN-D2 | H3012: 46276.653 | I3012: 46276.678 | J3012: 46276.686 | K3012: 46276.724 | L3012: 46276.735 | M3012: 46276.761 | N3012: 46276.775 | O3012: 46276.796 | P3012: 46276.806 | Q3012: 46276.826 | R3012: 771 | S3012: 0 | T3012: 0 | U3012: Completed | V3012: Space / Equipment | W3012: =IF(AND(X3012>=6,X3012<14),"A",IF(AND(X3012>=14,X3012<22),"B","C")) -> B | X3012: =HOUR(H3012) -> 15 | Y3012: =ROUND((I3012-H3012)*1440,0) -> 36 | Z3012: =ROUND((J3012-I3012)*1440,0) -> 11 | AA3012: =ROUND((K3012-J3012)*1440,0) -> 54 | AB3012: =ROUND((L3012-K3012)*1440,0) -> 17 | AC3012: =ROUND((M3012-L3012)*1440,0) -> 37 | AD3012: =IF(N3012="","",ROUND((N3012-M3012)*1440,0)) -> 20 | AE3012: =IF(O3012="","",ROUND((O3012-N3012)*1440,0)) -> 30 | AF3012: =IF(P3012="","",ROUND((P3012-O3012)*1440,0)) -> 14 | AG3012: =IF(Q3012="","",ROUND((Q3012-P3012)*1440,0)) -> 29 | AH3012: =IF(Q3012="","",ROUND((Q3012-H3012)*1440,0)) -> 248 | AI3012: =ROUND(IF(O3012="",Assumptions!$B$25-K3012,O3012-K3012)*24,1) -> 1.7 | AJ3012: =ROUND(MAX(N(Y3012)/Assumptions!$C$5, N(Z3012)/Assumptions!$C$6, N(AA3012)/Assumptions!$C$7, N(AB3012)/Assumptions!$C$8, N(AC3012)/Assumptions!$C$9, N(AD3012)/Assumptions!$C$10, N(AE3012)/Assumptions!$C$11, N(AF3012)/Assumptions!$C$12, N(AG3012)/Assumptions!$C$13),3) -> 1.2 | AK3012: =IF(OR(U3012="Pending",U3012="On Hold"),"Open GRN (awaiting)",IF(AJ3012<=1,"Within SLA",IF(ROUND(N(Y3012)/Assumptions!$C$5,3)=AJ3012,"Gate Wait",IF(ROUND(N(Z3012)/Assumptions!$C$6,3)=AJ3012,"Dock Wait",IF(ROUND(N(AA3012)/Assumptions!$C$7,3)=AJ3012,"Unloading",IF(ROUND(N(AB3012)/Assumptions!$C$8,3)=AJ3012,"Unload-to-QC Wait",IF(ROUND(N(AC3012)/Assumptions!$C$9,3)=AJ3012,"QC",IF(ROUND(N(AD3012)/Assumptions!$C$10,3)=AJ3012,"QC-to-GRN Wait",IF(ROUND(N(AE3012)/Assumptions!$C$11,3)=AJ3012,"GRN Processing",IF(ROUND(N(AF3012)/Assumptions!$C$12,3)=AJ3012,"GRN-to-Putaway Wait",IF(ROUND(N(AG3012)/Assumptions!$C$13,3)=AJ3012,"Putaway","Within SLA"))))))))))) -> Gate Wait
A3013: RCPT-03012 | B3013: PO-26-30776 | C3013: Vendor 09 | D3013: Bhiwandi DC | E3013: SKU-05-995 | F3013: Personal Care | G3013: BHW-D1 | H3013: 46276.671 | I3013: 46276.678 | J3013: 46276.684 | K3013: 46276.717 | L3013: 46276.726 | M3013: 46276.759 | N3013: 46276.778 | O3013: 46276.799 | P3013: 46276.804 | Q3013: 46276.817 | R3013: 342 | S3013: 0 | T3013: 0 | U3013: Completed | V3013: Vendor | W3013: =IF(AND(X3013>=6,X3013<14),"A",IF(AND(X3013>=14,X3013<22),"B","C")) -> B | X3013: =HOUR(H3013) -> 16 | Y3013: =ROUND((I3013-H3013)*1440,0) -> 11 | Z3013: =ROUND((J3013-I3013)*1440,0) -> 8 | AA3013: =ROUND((K3013-J3013)*1440,0) -> 47 | AB3013: =ROUND((L3013-K3013)*1440,0) -> 13 | AC3013: =ROUND((M3013-L3013)*1440,0) -> 48 | AD3013: =IF(N3013="","",ROUND((N3013-M3013)*1440,0)) -> 27 | AE3013: =IF(O3013="","",ROUND((O3013-N3013)*1440,0)) -> 30 | AF3013: =IF(P3013="","",ROUND((P3013-O3013)*1440,0)) -> 8 | AG3013: =IF(Q3013="","",ROUND((Q3013-P3013)*1440,0)) -> 19 | AH3013: =IF(Q3013="","",ROUND((Q3013-H3013)*1440,0)) -> 211 | AI3013: =ROUND(IF(O3013="",Assumptions!$B$25-K3013,O3013-K3013)*24,1) -> 2 | AJ3013: =ROUND(MAX(N(Y3013)/Assumptions!$C$5, N(Z3013)/Assumptions!$C$6, N(AA3013)/Assumptions!$C$7, N(AB3013)/Assumptions!$C$8, N(AC3013)/Assumptions!$C$9, N(AD3013)/Assumptions!$C$10, N(AE3013)/Assumptions!$C$11, N(AF3013)/Assumptions!$C$12, N(AG3013)/Assumptions!$C$13),3) -> 1.067 | AK3013: =IF(OR(U3013="Pending",U3013="On Hold"),"Open GRN (awaiting)",IF(AJ3013<=1,"Within SLA",IF(ROUND(N(Y3013)/Assumptions!$C$5,3)=AJ3013,"Gate Wait",IF(ROUND(N(Z3013)/Assumptions!$C$6,3)=AJ3013,"Dock Wait",IF(ROUND(N(AA3013)/Assumptions!$C$7,3)=AJ3013,"Unloading",IF(ROUND(N(AB3013)/Assumptions!$C$8,3)=AJ3013,"Unload-to-QC Wait",IF(ROUND(N(AC3013)/Assumptions!$C$9,3)=AJ3013,"QC",IF(ROUND(N(AD3013)/Assumptions!$C$10,3)=AJ3013,"QC-to-GRN Wait",IF(ROUND(N(AE3013)/Assumptions!$C$11,3)=AJ3013,"GRN Processing",IF(ROUND(N(AF3013)/Assumptions!$C$12,3)=AJ3013,"GRN-to-Putaway Wait",IF(ROUND(N(AG3013)/Assumptions!$C$13,3)=AJ3013,"Putaway","Within SLA"))))))))))) -> QC
A3014: RCPT-03013 | B3014: PO-26-61950 | C3014: Vendor 04 | D3014: Bhiwandi DC | E3014: SKU-05-728 | F3014: Personal Care | G3014: BHW-D2 | H3014: 46276.678 | I3014: 46276.704 | J3014: 46276.717 | K3014: 46276.735 | L3014: 46276.744 | M3014: 46276.77 | N3014: 46276.797 | O3014: 46276.804 | P3014: 46276.819 | Q3014: 46276.826 | R3014: 364 | S3014: 0 | T3014: 0 | U3014: Completed | V3014: Vendor | W3014: =IF(AND(X3014>=6,X3014<14),"A",IF(AND(X3014>=14,X3014<22),"B","C")) -> B | X3014: =HOUR(H3014) -> 16 | Y3014: =ROUND((I3014-H3014)*1440,0) -> 38 | Z3014: =ROUND((J3014-I3014)*1440,0) -> 18 | AA3014: =ROUND((K3014-J3014)*1440,0) -> 27 | AB3014: =ROUND((L3014-K3014)*1440,0) -> 12 | AC3014: =ROUND((M3014-L3014)*1440,0) -> 38 | AD3014: =IF(N3014="","",ROUND((N3014-M3014)*1440,0)) -> 38 | AE3014: =IF(O3014="","",ROUND((O3014-N3014)*1440,0)) -> 11 | AF3014: =IF(P3014="","",ROUND((P3014-O3014)*1440,0)) -> 21 | AG3014: =IF(Q3014="","",ROUND((Q3014-P3014)*1440,0)) -> 11 | AH3014: =IF(Q3014="","",ROUND((Q3014-H3014)*1440,0)) -> 214 | AI3014: =ROUND(IF(O3014="",Assumptions!$B$25-K3014,O3014-K3014)*24,1) -> 1.7 | AJ3014: =ROUND(MAX(N(Y3014)/Assumptions!$C$5, N(Z3014)/Assumptions!$C$6, N(AA3014)/Assumptions!$C$7, N(AB3014)/Assumptions!$C$8, N(AC3014)/Assumptions!$C$9, N(AD3014)/Assumptions!$C$10, N(AE3014)/Assumptions!$C$11, N(AF3014)/Assumptions!$C$12, N(AG3014)/Assumptions!$C$13),3) -> 1.267 | AK3014: =IF(OR(U3014="Pending",U3014="On Hold"),"Open GRN (awaiting)",IF(AJ3014<=1,"Within SLA",IF(ROUND(N(Y3014)/Assumptions!$C$5,3)=AJ3014,"Gate Wait",IF(ROUND(N(Z3014)/Assumptions!$C$6,3)=AJ3014,"Dock Wait",IF(ROUND(N(AA3014)/Assumptions!$C$7,3)=AJ3014,"Unloading",IF(ROUND(N(AB3014)/Assumptions!$C$8,3)=AJ3014,"Unload-to-QC Wait",IF(ROUND(N(AC3014)/Assumptions!$C$9,3)=AJ3014,"QC",IF(ROUND(N(AD3014)/Assumptions!$C$10,3)=AJ3014,"QC-to-GRN Wait",IF(ROUND(N(AE3014)/Assumptions!$C$11,3)=AJ3014,"GRN Processing",IF(ROUND(N(AF3014)/Assumptions!$C$12,3)=AJ3014,"GRN-to-Putaway Wait",IF(ROUND(N(AG3014)/Assumptions!$C$13,3)=AJ3014,"Putaway","Within SLA"))))))))))) -> Gate Wait
A3015: RCPT-03014 | B3015: PO-26-68175 | C3015: Vendor 05 | D3015: Pimplas DC | E3015: SKU-03-739 | F3015: Home Care | G3015: PMP-D2 | H3015: 46276.678 | I3015: 46276.688 | J3015: 46276.694 | K3015: 46276.728 | L3015: 46276.737 | M3015: 46276.767 | N3015: 46276.772 | O3015: 46276.797 | P3015: 46276.815 | Q3015: 46276.826 | R3015: 436 | S3015: 0 | T3015: 0 | U3015: Completed | V3015: Manpower | W3015: =IF(AND(X3015>=6,X3015<14),"A",IF(AND(X3015>=14,X3015<22),"B","C")) -> B | X3015: =HOUR(H3015) -> 16 | Y3015: =ROUND((I3015-H3015)*1440,0) -> 14 | Z3015: =ROUND((J3015-I3015)*1440,0) -> 9 | AA3015: =ROUND((K3015-J3015)*1440,0) -> 49 | AB3015: =ROUND((L3015-K3015)*1440,0) -> 12 | AC3015: =ROUND((M3015-L3015)*1440,0) -> 43 | AD3015: =IF(N3015="","",ROUND((N3015-M3015)*1440,0)) -> 7 | AE3015: =IF(O3015="","",ROUND((O3015-N3015)*1440,0)) -> 36 | AF3015: =IF(P3015="","",ROUND((P3015-O3015)*1440,0)) -> 27 | AG3015: =IF(Q3015="","",ROUND((Q3015-P3015)*1440,0)) -> 16 | AH3015: =IF(Q3015="","",ROUND((Q3015-H3015)*1440,0)) -> 213 | AI3015: =ROUND(IF(O3015="",Assumptions!$B$25-K3015,O3015-K3015)*24,1) -> 1.6 | AJ3015: =ROUND(MAX(N(Y3015)/Assumptions!$C$5, N(Z3015)/Assumptions!$C$6, N(AA3015)/Assumptions!$C$7, N(AB3015)/Assumptions!$C$8, N(AC3015)/Assumptions!$C$9, N(AD3015)/Assumptions!$C$10, N(AE3015)/Assumptions!$C$11, N(AF3015)/Assumptions!$C$12, N(AG3015)/Assumptions!$C$13),3) -> 1.35 | AK3015: =IF(OR(U3015="Pending",U3015="On Hold"),"Open GRN (awaiting)",IF(AJ3015<=1,"Within SLA",IF(ROUND(N(Y3015)/Assumptions!$C$5,3)=AJ3015,"Gate Wait",IF(ROUND(N(Z3015)/Assumptions!$C$6,3)=AJ3015,"Dock Wait",IF(ROUND(N(AA3015)/Assumptions!$C$7,3)=AJ3015,"Unloading",IF(ROUND(N(AB3015)/Assumptions!$C$8,3)=AJ3015,"Unload-to-QC Wait",IF(ROUND(N(AC3015)/Assumptions!$C$9,3)=AJ3015,"QC",IF(ROUND(N(AD3015)/Assumptions!$C$10,3)=AJ3015,"QC-to-GRN Wait",IF(ROUND(N(AE3015)/Assumptions!$C$11,3)=AJ3015,"GRN Processing",IF(ROUND(N(AF3015)/Assumptions!$C$12,3)=AJ3015,"GRN-to-Putaway Wait",IF(ROUND(N(AG3015)/Assumptions!$C$13,3)=AJ3015,"Putaway","Within SLA"))))))))))) -> GRN-to-Putaway Wait
A3016: RCPT-03015 | B3016: PO-26-47030 | C3016: Vendor 03 | D3016: Kalyan DC | E3016: SKU-01-378 | F3016: Beverages | G3016: KLN-D2 | H3016: 46276.687 | I3016: 46276.713 | J3016: 46276.716 | K3016: 46276.762 | L3016: 46276.782 | M3016: 46276.838 | N3016: 46276.972 | O3016: 46277.004 | P3016: 46277.015 | Q3016: 46277.029 | R3016: 1175 | S3016: 0 | T3016: 11 | U3016: Completed - Discrepancy | V3016: Documentation Mismatch | W3016: =IF(AND(X3016>=6,X3016<14),"A",IF(AND(X3016>=14,X3016<22),"B","C")) -> B | X3016: =HOUR(H3016) -> 16 | Y3016: =ROUND((I3016-H3016)*1440,0) -> 37 | Z3016: =ROUND((J3016-I3016)*1440,0) -> 5 | AA3016: =ROUND((K3016-J3016)*1440,0) -> 66 | AB3016: =ROUND((L3016-K3016)*1440,0) -> 29 | AC3016: =ROUND((M3016-L3016)*1440,0) -> 80 | AD3016: =IF(N3016="","",ROUND((N3016-M3016)*1440,0)) -> 194 | AE3016: =IF(O3016="","",ROUND((O3016-N3016)*1440,0)) -> 46 | AF3016: =IF(P3016="","",ROUND((P3016-O3016)*1440,0)) -> 16 | AG3016: =IF(Q3016="","",ROUND((Q3016-P3016)*1440,0)) -> 20 | AH3016: =IF(Q3016="","",ROUND((Q3016-H3016)*1440,0)) -> 493 | AI3016: =ROUND(IF(O3016="",Assumptions!$B$25-K3016,O3016-K3016)*24,1) -> 5.8 | AJ3016: =ROUND(MAX(N(Y3016)/Assumptions!$C$5, N(Z3016)/Assumptions!$C$6, N(AA3016)/Assumptions!$C$7, N(AB3016)/Assumptions!$C$8, N(AC3016)/Assumptions!$C$9, N(AD3016)/Assumptions!$C$10, N(AE3016)/Assumptions!$C$11, N(AF3016)/Assumptions!$C$12, N(AG3016)/Assumptions!$C$13),3) -> 6.467 | AK3016: =IF(OR(U3016="Pending",U3016="On Hold"),"Open GRN (awaiting)",IF(AJ3016<=1,"Within SLA",IF(ROUND(N(Y3016)/Assumptions!$C$5,3)=AJ3016,"Gate Wait",IF(ROUND(N(Z3016)/Assumptions!$C$6,3)=AJ3016,"Dock Wait",IF(ROUND(N(AA3016)/Assumptions!$C$7,3)=AJ3016,"Unloading",IF(ROUND(N(AB3016)/Assumptions!$C$8,3)=AJ3016,"Unload-to-QC Wait",IF(ROUND(N(AC3016)/Assumptions!$C$9,3)=AJ3016,"QC",IF(ROUND(N(AD3016)/Assumptions!$C$10,3)=AJ3016,"QC-to-GRN Wait",IF(ROUND(N(AE3016)/Assumptions!$C$11,3)=AJ3016,"GRN Processing",IF(ROUND(N(AF3016)/Assumptions!$C$12,3)=AJ3016,"GRN-to-Putaway Wait",IF(ROUND(N(AG3016)/Assumptions!$C$13,3)=AJ3016,"Putaway","Within SLA"))))))))))) -> QC-to-GRN Wait
A3017: RCPT-03016 | B3017: PO-26-15946 | C3017: Vendor 08 | D3017: Pimplas DC | E3017: SKU-02-377 | F3017: Dairy & Frozen | G3017: PMP-D1 | H3017: 46276.692 | I3017: 46276.703 | J3017: 46276.711 | K3017: 46276.731 | L3017: 46276.738 | M3017: 46276.753 | N3017: 46276.853 | O3017: 46276.885 | P3017: 46276.91 | Q3017: 46276.949 | R3017: 322 | S3017: 0 | T3017: 0 | U3017: Completed | V3017: System | W3017: =IF(AND(X3017>=6,X3017<14),"A",IF(AND(X3017>=14,X3017<22),"B","C")) -> B | X3017: =HOUR(H3017) -> 16 | Y3017: =ROUND((I3017-H3017)*1440,0) -> 16 | Z3017: =ROUND((J3017-I3017)*1440,0) -> 12 | AA3017: =ROUND((K3017-J3017)*1440,0) -> 29 | AB3017: =ROUND((L3017-K3017)*1440,0) -> 9 | AC3017: =ROUND((M3017-L3017)*1440,0) -> 23 | AD3017: =IF(N3017="","",ROUND((N3017-M3017)*1440,0)) -> 143 | AE3017: =IF(O3017="","",ROUND((O3017-N3017)*1440,0)) -> 46 | AF3017: =IF(P3017="","",ROUND((P3017-O3017)*1440,0)) -> 36 | AG3017: =IF(Q3017="","",ROUND((Q3017-P3017)*1440,0)) -> 56 | AH3017: =IF(Q3017="","",ROUND((Q3017-H3017)*1440,0)) -> 370 | AI3017: =ROUND(IF(O3017="",Assumptions!$B$25-K3017,O3017-K3017)*24,1) -> 3.7 | AJ3017: =ROUND(MAX(N(Y3017)/Assumptions!$C$5, N(Z3017)/Assumptions!$C$6, N(AA3017)/Assumptions!$C$7, N(AB3017)/Assumptions!$C$8, N(AC3017)/Assumptions!$C$9, N(AD3017)/Assumptions!$C$10, N(AE3017)/Assumptions!$C$11, N(AF3017)/Assumptions!$C$12, N(AG3017)/Assumptions!$C$13),3) -> 4.767 | AK3017: =IF(OR(U3017="Pending",U3017="On Hold"),"Open GRN (awaiting)",IF(AJ3017<=1,"Within SLA",IF(ROUND(N(Y3017)/Assumptions!$C$5,3)=AJ3017,"Gate Wait",IF(ROUND(N(Z3017)/Assumptions!$C$6,3)=AJ3017,"Dock Wait",IF(ROUND(N(AA3017)/Assumptions!$C$7,3)=AJ3017,"Unloading",IF(ROUND(N(AB3017)/Assumptions!$C$8,3)=AJ3017,"Unload-to-QC Wait",IF(ROUND(N(AC3017)/Assumptions!$C$9,3)=AJ3017,"QC",IF(ROUND(N(AD3017)/Assumptions!$C$10,3)=AJ3017,"QC-to-GRN Wait",IF(ROUND(N(AE3017)/Assumptions!$C$11,3)=AJ3017,"GRN Processing",IF(ROUND(N(AF3017)/Assumptions!$C$12,3)=AJ3017,"GRN-to-Putaway Wait",IF(ROUND(N(AG3017)/Assumptions!$C$13,3)=AJ3017,"Putaway","Within SLA"))))))))))) -> QC-to-GRN Wait
A3018: RCPT-03017 | B3018: PO-26-95892 | C3018: Vendor 05 | D3018: Bhiwandi DC | E3018: SKU-03-897 | F3018: Home Care | G3018: BHW-D2 | H3018: 46276.725 | I3018: 46276.738 | J3018: 46276.752 | K3018: 46276.762 | L3018: 46276.767 | M3018: 46276.783 | N3018: 46276.846 | O3018: 46276.876 | P3018: 46276.901 | Q3018: 46276.913 | R3018: 206 | S3018: 0 | T3018: 0 | U3018: Completed | V3018: Documentation Mismatch | W3018: =IF(AND(X3018>=6,X3018<14),"A",IF(AND(X3018>=14,X3018<22),"B","C")) -> B | X3018: =HOUR(H3018) -> 17 | Y3018: =ROUND((I3018-H3018)*1440,0) -> 19 | Z3018: =ROUND((J3018-I3018)*1440,0) -> 20 | AA3018: =ROUND((K3018-J3018)*1440,0) -> 15 | AB3018: =ROUND((L3018-K3018)*1440,0) -> 7 | AC3018: =ROUND((M3018-L3018)*1440,0) -> 23 | AD3018: =IF(N3018="","",ROUND((N3018-M3018)*1440,0)) -> 90 | AE3018: =IF(O3018="","",ROUND((O3018-N3018)*1440,0)) -> 44 | AF3018: =IF(P3018="","",ROUND((P3018-O3018)*1440,0)) -> 35 | AG3018: =IF(Q3018="","",ROUND((Q3018-P3018)*1440,0)) -> 18 | AH3018: =IF(Q3018="","",ROUND((Q3018-H3018)*1440,0)) -> 271 | AI3018: =ROUND(IF(O3018="",Assumptions!$B$25-K3018,O3018-K3018)*24,1) -> 2.7 | AJ3018: =ROUND(MAX(N(Y3018)/Assumptions!$C$5, N(Z3018)/Assumptions!$C$6, N(AA3018)/Assumptions!$C$7, N(AB3018)/Assumptions!$C$8, N(AC3018)/Assumptions!$C$9, N(AD3018)/Assumptions!$C$10, N(AE3018)/Assumptions!$C$11, N(AF3018)/Assumptions!$C$12, N(AG3018)/Assumptions!$C$13),3) -> 3 | AK3018: =IF(OR(U3018="Pending",U3018="On Hold"),"Open GRN (awaiting)",IF(AJ3018<=1,"Within SLA",IF(ROUND(N(Y3018)/Assumptions!$C$5,3)=AJ3018,"Gate Wait",IF(ROUND(N(Z3018)/Assumptions!$C$6,3)=AJ3018,"Dock Wait",IF(ROUND(N(AA3018)/Assumptions!$C$7,3)=AJ3018,"Unloading",IF(ROUND(N(AB3018)/Assumptions!$C$8,3)=AJ3018,"Unload-to-QC Wait",IF(ROUND(N(AC3018)/Assumptions!$C$9,3)=AJ3018,"QC",IF(ROUND(N(AD3018)/Assumptions!$C$10,3)=AJ3018,"QC-to-GRN Wait",IF(ROUND(N(AE3018)/Assumptions!$C$11,3)=AJ3018,"GRN Processing",IF(ROUND(N(AF3018)/Assumptions!$C$12,3)=AJ3018,"GRN-to-Putaway Wait",IF(ROUND(N(AG3018)/Assumptions!$C$13,3)=AJ3018,"Putaway","Within SLA"))))))))))) -> QC-to-GRN Wait
A3019: RCPT-03018 | B3019: PO-26-42999 | C3019: Vendor 02 | D3019: Kalyan DC | E3019: SKU-06-554 | F3019: Snacks | G3019: KLN-D2 | H3019: 46276.729 | I3019: 46276.735 | J3019: 46276.744 | K3019: 46276.772 | L3019: 46276.786 | M3019: 46276.804 | N3019: 46276.815 | O3019: 46276.84 | P3019: 46276.856 | Q3019: 46276.871 | R3019: 289 | S3019: 0 | T3019: 0 | U3019: Completed | V3019: Space / Equipment | W3019: =IF(AND(X3019>=6,X3019<14),"A",IF(AND(X3019>=14,X3019<22),"B","C")) -> B | X3019: =HOUR(H3019) -> 17 | Y3019: =ROUND((I3019-H3019)*1440,0) -> 9 | Z3019: =ROUND((J3019-I3019)*1440,0) -> 13 | AA3019: =ROUND((K3019-J3019)*1440,0) -> 40 | AB3019: =ROUND((L3019-K3019)*1440,0) -> 20 | AC3019: =ROUND((M3019-L3019)*1440,0) -> 26 | AD3019: =IF(N3019="","",ROUND((N3019-M3019)*1440,0)) -> 16 | AE3019: =IF(O3019="","",ROUND((O3019-N3019)*1440,0)) -> 36 | AF3019: =IF(P3019="","",ROUND((P3019-O3019)*1440,0)) -> 22 | AG3019: =IF(Q3019="","",ROUND((Q3019-P3019)*1440,0)) -> 22 | AH3019: =IF(Q3019="","",ROUND((Q3019-H3019)*1440,0)) -> 204 | AI3019: =ROUND(IF(O3019="",Assumptions!$B$25-K3019,O3019-K3019)*24,1) -> 1.6 | AJ3019: =ROUND(MAX(N(Y3019)/Assumptions!$C$5, N(Z3019)/Assumptions!$C$6, N(AA3019)/Assumptions!$C$7, N(AB3019)/Assumptions!$C$8, N(AC3019)/Assumptions!$C$9, N(AD3019)/Assumptions!$C$10, N(AE3019)/Assumptions!$C$11, N(AF3019)/Assumptions!$C$12, N(AG3019)/Assumptions!$C$13),3) -> 1.333 | AK3019: =IF(OR(U3019="Pending",U3019="On Hold"),"Open GRN (awaiting)",IF(AJ3019<=1,"Within SLA",IF(ROUND(N(Y3019)/Assumptions!$C$5,3)=AJ3019,"Gate Wait",IF(ROUND(N(Z3019)/Assumptions!$C$6,3)=AJ3019,"Dock Wait",IF(ROUND(N(AA3019)/Assumptions!$C$7,3)=AJ3019,"Unloading",IF(ROUND(N(AB3019)/Assumptions!$C$8,3)=AJ3019,"Unload-to-QC Wait",IF(ROUND(N(AC3019)/Assumptions!$C$9,3)=AJ3019,"QC",IF(ROUND(N(AD3019)/Assumptions!$C$10,3)=AJ3019,"QC-to-GRN Wait",IF(ROUND(N(AE3019)/Assumptions!$C$11,3)=AJ3019,"GRN Processing",IF(ROUND(N(AF3019)/Assumptions!$C$12,3)=AJ3019,"GRN-to-Putaway Wait",IF(ROUND(N(AG3019)/Assumptions!$C$13,3)=AJ3019,"Putaway","Within SLA"))))))))))) -> Unload-to-QC Wait
A3020: RCPT-03019 | B3020: PO-26-47246 | C3020: Vendor 05 | D3020: Kalyan DC | E3020: SKU-03-393 | F3020: Home Care | G3020: KLN-D2 | H3020: 46276.733 | I3020: 46276.757 | J3020: 46276.766 | K3020: 46276.797 | L3020: 46276.806 | M3020: 46276.839 | N3020: 46276.849 | O3020: 46276.962 | P3020: 46276.969 | Q3020: 46276.98 | R3020: 308 | S3020: 0 | T3020: 0 | U3020: Completed | V3020: System | W3020: =IF(AND(X3020>=6,X3020<14),"A",IF(AND(X3020>=14,X3020<22),"B","C")) -> B | X3020: =HOUR(H3020) -> 17 | Y3020: =ROUND((I3020-H3020)*1440,0) -> 34 | Z3020: =ROUND((J3020-I3020)*1440,0) -> 13 | AA3020: =ROUND((K3020-J3020)*1440,0) -> 45 | AB3020: =ROUND((L3020-K3020)*1440,0) -> 12 | AC3020: =ROUND((M3020-L3020)*1440,0) -> 48 | AD3020: =IF(N3020="","",ROUND((N3020-M3020)*1440,0)) -> 14 | AE3020: =IF(O3020="","",ROUND((O3020-N3020)*1440,0)) -> 163 | AF3020: =IF(P3020="","",ROUND((P3020-O3020)*1440,0)) -> 10 | AG3020: =IF(Q3020="","",ROUND((Q3020-P3020)*1440,0)) -> 16 | AH3020: =IF(Q3020="","",ROUND((Q3020-H3020)*1440,0)) -> 355 | AI3020: =ROUND(IF(O3020="",Assumptions!$B$25-K3020,O3020-K3020)*24,1) -> 4 | AJ3020: =ROUND(MAX(N(Y3020)/Assumptions!$C$5, N(Z3020)/Assumptions!$C$6, N(AA3020)/Assumptions!$C$7, N(AB3020)/Assumptions!$C$8, N(AC3020)/Assumptions!$C$9, N(AD3020)/Assumptions!$C$10, N(AE3020)/Assumptions!$C$11, N(AF3020)/Assumptions!$C$12, N(AG3020)/Assumptions!$C$13),3) -> 3.622 | AK3020: =IF(OR(U3020="Pending",U3020="On Hold"),"Open GRN (awaiting)",IF(AJ3020<=1,"Within SLA",IF(ROUND(N(Y3020)/Assumptions!$C$5,3)=AJ3020,"Gate Wait",IF(ROUND(N(Z3020)/Assumptions!$C$6,3)=AJ3020,"Dock Wait",IF(ROUND(N(AA3020)/Assumptions!$C$7,3)=AJ3020,"Unloading",IF(ROUND(N(AB3020)/Assumptions!$C$8,3)=AJ3020,"Unload-to-QC Wait",IF(ROUND(N(AC3020)/Assumptions!$C$9,3)=AJ3020,"QC",IF(ROUND(N(AD3020)/Assumptions!$C$10,3)=AJ3020,"QC-to-GRN Wait",IF(ROUND(N(AE3020)/Assumptions!$C$11,3)=AJ3020,"GRN Processing",IF(ROUND(N(AF3020)/Assumptions!$C$12,3)=AJ3020,"GRN-to-Putaway Wait",IF(ROUND(N(AG3020)/Assumptions!$C$13,3)=AJ3020,"Putaway","Within SLA"))))))))))) -> GRN Processing
A3021: RCPT-03020 | B3021: PO-26-59628 | C3021: Vendor 05 | D3021: Bhiwandi DC | E3021: SKU-03-465 | F3021: Home Care | G3021: BHW-D2 | H3021: 46276.735 | I3021: 46276.831 | J3021: 46276.835 | K3021: 46276.883 | L3021: 46276.889 | M3021: 46276.899 | N3021: 46276.906 | O3021: 46276.942 | P3021: 46276.965 | Q3021: 46276.974 | R3021: 482 | S3021: 0 | T3021: 0 | U3021: Completed | V3021: Space / Equipment | W3021: =IF(AND(X3021>=6,X3021<14),"A",IF(AND(X3021>=14,X3021<22),"B","C")) -> B | X3021: =HOUR(H3021) -> 17 | Y3021: =ROUND((I3021-H3021)*1440,0) -> 138 | Z3021: =ROUND((J3021-I3021)*1440,0) -> 6 | AA3021: =ROUND((K3021-J3021)*1440,0) -> 70 | AB3021: =ROUND((L3021-K3021)*1440,0) -> 8 | AC3021: =ROUND((M3021-L3021)*1440,0) -> 15 | AD3021: =IF(N3021="","",ROUND((N3021-M3021)*1440,0)) -> 9 | AE3021: =IF(O3021="","",ROUND((O3021-N3021)*1440,0)) -> 53 | AF3021: =IF(P3021="","",ROUND((P3021-O3021)*1440,0)) -> 32 | AG3021: =IF(Q3021="","",ROUND((Q3021-P3021)*1440,0)) -> 14 | AH3021: =IF(Q3021="","",ROUND((Q3021-H3021)*1440,0)) -> 345 | AI3021: =ROUND(IF(O3021="",Assumptions!$B$25-K3021,O3021-K3021)*24,1) -> 1.4 | AJ3021: =ROUND(MAX(N(Y3021)/Assumptions!$C$5, N(Z3021)/Assumptions!$C$6, N(AA3021)/Assumptions!$C$7, N(AB3021)/Assumptions!$C$8, N(AC3021)/Assumptions!$C$9, N(AD3021)/Assumptions!$C$10, N(AE3021)/Assumptions!$C$11, N(AF3021)/Assumptions!$C$12, N(AG3021)/Assumptions!$C$13),3) -> 4.6 | AK3021: =IF(OR(U3021="Pending",U3021="On Hold"),"Open GRN (awaiting)",IF(AJ3021<=1,"Within SLA",IF(ROUND(N(Y3021)/Assumptions!$C$5,3)=AJ3021,"Gate Wait",IF(ROUND(N(Z3021)/Assumptions!$C$6,3)=AJ3021,"Dock Wait",IF(ROUND(N(AA3021)/Assumptions!$C$7,3)=AJ3021,"Unloading",IF(ROUND(N(AB3021)/Assumptions!$C$8,3)=AJ3021,"Unload-to-QC Wait",IF(ROUND(N(AC3021)/Assumptions!$C$9,3)=AJ3021,"QC",IF(ROUND(N(AD3021)/Assumptions!$C$10,3)=AJ3021,"QC-to-GRN Wait",IF(ROUND(N(AE3021)/Assumptions!$C$11,3)=AJ3021,"GRN Processing",IF(ROUND(N(AF3021)/Assumptions!$C$12,3)=AJ3021,"GRN-to-Putaway Wait",IF(ROUND(N(AG3021)/Assumptions!$C$13,3)=AJ3021,"Putaway","Within SLA"))))))))))) -> Gate Wait
... A3038: RCPT-03037 | B3038: PO-26-26203 | C3038: Vendor 03 | D3038: Bhiwandi DC | E3038: SKU-01-638 | F3038: Beverages | G3038: BHW-D1 | H3038: 46277.31 | I3038: 46277.327 | J3038: 46277.332 | K3038: 46277.356 | L3038: 46277.369 | M3038: 46277.416 | N3038: 46277.453 | O3038: 46277.501 | P3038: 46277.511 | Q3038: 46277.522 | R3038: 295 | S3038: 0 | T3038: 0 | U3038: Completed | V3038: Manpower | W3038: =IF(AND(X3038>=6,X3038<14),"A",IF(AND(X3038>=14,X3038<22),"B","C")) -> A | X3038: =HOUR(H3038) -> 7 | Y3038: =ROUND((I3038-H3038)*1440,0) -> 25 | Z3038: =ROUND((J3038-I3038)*1440,0) -> 7 | AA3038: =ROUND((K3038-J3038)*1440,0) -> 34 | AB3038: =ROUND((L3038-K3038)*1440,0) -> 19 | AC3038: =ROUND((M3038-L3038)*1440,0) -> 68 | AD3038: =IF(N3038="","",ROUND((N3038-M3038)*1440,0)) -> 54 | AE3038: =IF(O3038="","",ROUND((O3038-N3038)*1440,0)) -> 69 | AF3038: =IF(P3038="","",ROUND((P3038-O3038)*1440,0)) -> 14 | AG3038: =IF(Q3038="","",ROUND((Q3038-P3038)*1440,0)) -> 16 | AH3038: =IF(Q3038="","",ROUND((Q3038-H3038)*1440,0)) -> 306 | AI3038: =ROUND(IF(O3038="",Assumptions!$B$25-K3038,O3038-K3038)*24,1) -> 3.5 | AJ3038: =ROUND(MAX(N(Y3038)/Assumptions!$C$5, N(Z3038)/Assumptions!$C$6, N(AA3038)/Assumptions!$C$7, N(AB3038)/Assumptions!$C$8, N(AC3038)/Assumptions!$C$9, N(AD3038)/Assumptions!$C$10, N(AE3038)/Assumptions!$C$11, N(AF3038)/Assumptions!$C$12, N(AG3038)/Assumptions!$C$13),3) -> 1.8 | AK3038: =IF(OR(U3038="Pending",U3038="On Hold"),"Open GRN (awaiting)",IF(AJ3038<=1,"Within SLA",IF(ROUND(N(Y3038)/Assumptions!$C$5,3)=AJ3038,"Gate Wait",IF(ROUND(N(Z3038)/Assumptions!$C$6,3)=AJ3038,"Dock Wait",IF(ROUND(N(AA3038)/Assumptions!$C$7,3)=AJ3038,"Unloading",IF(ROUND(N(AB3038)/Assumptions!$C$8,3)=AJ3038,"Unload-to-QC Wait",IF(ROUND(N(AC3038)/Assumptions!$C$9,3)=AJ3038,"QC",IF(ROUND(N(AD3038)/Assumptions!$C$10,3)=AJ3038,"QC-to-GRN Wait",IF(ROUND(N(AE3038)/Assumptions!$C$11,3)=AJ3038,"GRN Processing",IF(ROUND(N(AF3038)/Assumptions!$C$12,3)=AJ3038,"GRN-to-Putaway Wait",IF(ROUND(N(AG3038)/Assumptions!$C$13,3)=AJ3038,"Putaway","Within SLA"))))))))))) -> QC-to-GRN Wait
A3039: RCPT-03038 | B3039: PO-26-44668 | C3039: Vendor 07 | D3039: Bhiwandi DC | E3039: SKU-04-646 | F3039: Packaging | G3039: BHW-D2 | H3039: 46277.331 | I3039: 46277.34 | J3039: 46277.348 | K3039: 46277.376 | L3039: 46277.393 | M3039: 46277.41 | R3039: 215 | S3039: 0 | T3039: 0 | U3039: On Hold | V3039: Vendor | W3039: =IF(AND(X3039>=6,X3039<14),"A",IF(AND(X3039>=14,X3039<22),"B","C")) -> A | X3039: =HOUR(H3039) -> 7 | Y3039: =ROUND((I3039-H3039)*1440,0) -> 13 | Z3039: =ROUND((J3039-I3039)*1440,0) -> 12 | AA3039: =ROUND((K3039-J3039)*1440,0) -> 41 | AB3039: =ROUND((L3039-K3039)*1440,0) -> 24 | AC3039: =ROUND((M3039-L3039)*1440,0) -> 24 | AD3039: =IF(N3039="","",ROUND((N3039-M3039)*1440,0)) | AE3039: =IF(O3039="","",ROUND((O3039-N3039)*1440,0)) | AF3039: =IF(P3039="","",ROUND((P3039-O3039)*1440,0)) | AG3039: =IF(Q3039="","",ROUND((Q3039-P3039)*1440,0)) | AH3039: =IF(Q3039="","",ROUND((Q3039-H3039)*1440,0)) | AI3039: =ROUND(IF(O3039="",Assumptions!$B$25-K3039,O3039-K3039)*24,1) -> 479 | AJ3039: =ROUND(MAX(N(Y3039)/Assumptions!$C$5, N(Z3039)/Assumptions!$C$6, N(AA3039)/Assumptions!$C$7, N(AB3039)/Assumptions!$C$8, N(AC3039)/Assumptions!$C$9, N(AD3039)/Assumptions!$C$10, N(AE3039)/Assumptions!$C$11, N(AF3039)/Assumptions!$C$12, N(AG3039)/Assumptions!$C$13),3) -> 1.6 | AK3039: =IF(OR(U3039="Pending",U3039="On Hold"),"Open GRN (awaiting)",IF(AJ3039<=1,"Within SLA",IF(ROUND(N(Y3039)/Assumptions!$C$5,3)=AJ3039,"Gate Wait",IF(ROUND(N(Z3039)/Assumptions!$C$6,3)=AJ3039,"Dock Wait",IF(ROUND(N(AA3039)/Assumptions!$C$7,3)=AJ3039,"Unloading",IF(ROUND(N(AB3039)/Assumptions!$C$8,3)=AJ3039,"Unload-to-QC Wait",IF(ROUND(N(AC3039)/Assumptions!$C$9,3)=AJ3039,"QC",IF(ROUND(N(AD3039)/Assumptions!$C$10,3)=AJ3039,"QC-to-GRN Wait",IF(ROUND(N(AE3039)/Assumptions!$C$11,3)=AJ3039,"GRN Processing",IF(ROUND(N(AF3039)/Assumptions!$C$12,3)=AJ3039,"GRN-to-Putaway Wait",IF(ROUND(N(AG3039)/Assumptions!$C$13,3)=AJ3039,"Putaway","Within SLA"))))))))))) -> Open GRN (awaiting)
